<?xml version="1.0" encoding="UTF-8"?><testrun name="HsqldbUserDaoTest" project="usermanagement" tests="5" started="5" failures="1" errors="1" ignored="0">
  <testsuite name="ua.nure.cs.kondratiuk.usermanagement.db.HsqldbUserDaoTest" time="0.176">
    <testcase name="testFindAll" classname="ua.nure.cs.kondratiuk.usermanagement.db.HsqldbUserDaoTest" time="0.151"/>
    <testcase name="testFind" classname="ua.nure.cs.kondratiuk.usermanagement.db.HsqldbUserDaoTest" time="0.009">
      <failure>junit.framework.AssertionFailedError&#13;
	at junit.framework.Assert.fail(Assert.java:55)&#13;
	at junit.framework.Assert.assertTrue(Assert.java:22)&#13;
	at junit.framework.Assert.assertNotNull(Assert.java:256)&#13;
	at junit.framework.Assert.assertNotNull(Assert.java:248)&#13;
	at junit.framework.TestCase.assertNotNull(TestCase.java:417)&#13;
	at ua.nure.cs.kondratiuk.usermanagement.db.HsqldbUserDaoTest.testFind(HsqldbUserDaoTest.java:54)&#13;
	at sun.reflect.NativeMethodAccessorImpl.invoke0(Native Method)&#13;
	at sun.reflect.NativeMethodAccessorImpl.invoke(Unknown Source)&#13;
	at sun.reflect.DelegatingMethodAccessorImpl.invoke(Unknown Source)&#13;
	at java.lang.reflect.Method.invoke(Unknown Source)&#13;
	at junit.framework.TestCase.runTest(TestCase.java:176)&#13;
	at junit.framework.TestCase.runBare(TestCase.java:141)&#13;
	at junit.framework.TestResult$1.protect(TestResult.java:122)&#13;
	at junit.framework.TestResult.runProtected(TestResult.java:142)&#13;
	at junit.framework.TestResult.run(TestResult.java:125)&#13;
	at junit.framework.TestCase.run(TestCase.java:129)&#13;
	at junit.framework.TestSuite.runTest(TestSuite.java:252)&#13;
	at junit.framework.TestSuite.run(TestSuite.java:247)&#13;
	at org.eclipse.jdt.internal.junit.runner.junit3.JUnit3TestReference.run(JUnit3TestReference.java:124)&#13;
	at org.eclipse.jdt.internal.junit.runner.TestExecution.run(TestExecution.java:41)&#13;
	at org.eclipse.jdt.internal.junit.runner.RemoteTestRunner.runTests(RemoteTestRunner.java:541)&#13;
	at org.eclipse.jdt.internal.junit.runner.RemoteTestRunner.runTests(RemoteTestRunner.java:763)&#13;
	at org.eclipse.jdt.internal.junit.runner.RemoteTestRunner.run(RemoteTestRunner.java:463)&#13;
	at org.eclipse.jdt.internal.junit.runner.RemoteTestRunner.main(RemoteTestRunner.java:209)&#13;
&#13;
</failure>
    </testcase>
    <testcase name="testCreate" classname="ua.nure.cs.kondratiuk.usermanagement.db.HsqldbUserDaoTest" time="0.006"/>
    <testcase name="testDelete" classname="ua.nure.cs.kondratiuk.usermanagement.db.HsqldbUserDaoTest" time="0.005">
      <error>ua.nure.cs.kondratiuk.usermanagement.db.DatabaseExeption: java.sql.SQLException: No data is available&#13;
	at ua.nure.cs.kondratiuk.usermanagement.db.HsqldbUserDao.find(HsqldbUserDao.java:88)&#13;
	at ua.nure.cs.kondratiuk.usermanagement.db.HsqldbUserDaoTest.testDelete(HsqldbUserDaoTest.java:70)&#13;
	at sun.reflect.NativeMethodAccessorImpl.invoke0(Native Method)&#13;
	at sun.reflect.NativeMethodAccessorImpl.invoke(Unknown Source)&#13;
	at sun.reflect.DelegatingMethodAccessorImpl.invoke(Unknown Source)&#13;
	at java.lang.reflect.Method.invoke(Unknown Source)&#13;
	at junit.framework.TestCase.runTest(TestCase.java:176)&#13;
	at junit.framework.TestCase.runBare(TestCase.java:141)&#13;
	at junit.framework.TestResult$1.protect(TestResult.java:122)&#13;
	at junit.framework.TestResult.runProtected(TestResult.java:142)&#13;
	at junit.framework.TestResult.run(TestResult.java:125)&#13;
	at junit.framework.TestCase.run(TestCase.java:129)&#13;
	at junit.framework.TestSuite.runTest(TestSuite.java:252)&#13;
	at junit.framework.TestSuite.run(TestSuite.java:247)&#13;
	at org.eclipse.jdt.internal.junit.runner.junit3.JUnit3TestReference.run(JUnit3TestReference.java:124)&#13;
	at org.eclipse.jdt.internal.junit.runner.TestExecution.run(TestExecution.java:41)&#13;
	at org.eclipse.jdt.internal.junit.runner.RemoteTestRunner.runTests(RemoteTestRunner.java:541)&#13;
	at org.eclipse.jdt.internal.junit.runner.RemoteTestRunner.runTests(RemoteTestRunner.java:763)&#13;
	at org.eclipse.jdt.internal.junit.runner.RemoteTestRunner.run(RemoteTestRunner.java:463)&#13;
	at org.eclipse.jdt.internal.junit.runner.RemoteTestRunner.main(RemoteTestRunner.java:209)&#13;
Caused by: java.sql.SQLException: No data is available&#13;
	at org.hsqldb.jdbc.Util.sqlException(Unknown Source)&#13;
	at org.hsqldb.jdbc.Util.sqlException(Unknown Source)&#13;
	at org.hsqldb.jdbc.jdbcResultSet.checkAvailable(Unknown Source)&#13;
	at org.hsqldb.jdbc.jdbcResultSet.getColumnInType(Unknown Source)&#13;
	at org.hsqldb.jdbc.jdbcResultSet.getLong(Unknown Source)&#13;
	at ua.nure.cs.kondratiuk.usermanagement.db.HsqldbUserDao.find(HsqldbUserDao.java:80)&#13;
	... 19 more&#13;
&#13;
</error>
    </testcase>
    <testcase name="testUpdate" classname="ua.nure.cs.kondratiuk.usermanagement.db.HsqldbUserDaoTest" time="0.005"/>
  </testsuite>
</testrun>
